[2024-07-19 20:35:33,099] [INFO] [source.persistance.database] [database.py:47] Database context has been initialized
[2024-07-19 20:35:33,410] [INFO] [source.handlers] [__init__.py:29] 220 FTP Server ready.
[2024-07-19 20:35:33,610] [INFO] [source.handlers] [__init__.py:31] 230 User u165660_tg_bot logged in
[2024-07-19 20:35:33,616] [INFO] [__main__] [main.py:43] Application has been started
[2024-07-19 20:35:36,310] [INFO] [aiogram.dispatcher] [dispatcher.py:527] Start polling
[2024-07-19 20:35:36,487] [INFO] [aiogram.dispatcher] [dispatcher.py:341] Run polling for bot @pirat_themed_guest_house_bot id=7010190829 - 'Briz'
[2024-07-19 20:35:39,457] [INFO] [source.handlers.command] [command.py:50] event (chat '5663974991', command '6839', text '/start') has been accepted
[2024-07-19 20:35:41,492] [ERROR] [source.persistance.database] [database.py:98] An error occurred during database session
[2024-07-19 20:35:41,492] [ERROR] [source.handlers.command] [command.py:64] event (chat '5663974991', command '6839', text '/start') hasn't been processed correctly
Traceback (most recent call last):
  File "C:\Users\pc\Desktop\Projects\python\BrizBot\venv\lib\site-packages\aiomysql\connection.py", line 88, in _open_connection
    transport, _ = await loop.create_connection(
  File "C:\Users\pc\AppData\Local\Programs\Python\Python310\lib\asyncio\base_events.py", line 1040, in create_connection
    sock = await self._connect_sock(
  File "C:\Users\pc\AppData\Local\Programs\Python\Python310\lib\asyncio\base_events.py", line 954, in _connect_sock
    await self.sock_connect(sock, address)
  File "C:\Users\pc\AppData\Local\Programs\Python\Python310\lib\asyncio\proactor_events.py", line 704, in sock_connect
    return await self._proactor.connect(sock, address)
asyncio.exceptions.CancelledError

During handling of the above exception, another exception occurred:

Traceback (most recent call last):
  File "C:\Users\pc\AppData\Local\Programs\Python\Python310\lib\asyncio\tasks.py", line 458, in wait_for
    fut.result()
asyncio.exceptions.CancelledError

The above exception was the direct cause of the following exception:

Traceback (most recent call last):
  File "C:\Users\pc\Desktop\Projects\python\BrizBot\venv\lib\site-packages\aiomysql\connection.py", line 527, in _connect
    self._reader, self._writer = await \
  File "C:\Users\pc\AppData\Local\Programs\Python\Python310\lib\asyncio\tasks.py", line 460, in wait_for
    raise exceptions.TimeoutError() from exc
asyncio.exceptions.TimeoutError

The above exception was the direct cause of the following exception:

Traceback (most recent call last):
  File "C:\Users\pc\Desktop\Projects\python\BrizBot\venv\lib\site-packages\sqlalchemy\engine\base.py", line 146, in __init__
    self._dbapi_connection = engine.raw_connection()
  File "C:\Users\pc\Desktop\Projects\python\BrizBot\venv\lib\site-packages\sqlalchemy\engine\base.py", line 3300, in raw_connection
    return self.pool.connect()
  File "C:\Users\pc\Desktop\Projects\python\BrizBot\venv\lib\site-packages\sqlalchemy\pool\base.py", line 449, in connect
    return _ConnectionFairy._checkout(self)
  File "C:\Users\pc\Desktop\Projects\python\BrizBot\venv\lib\site-packages\sqlalchemy\pool\base.py", line 1263, in _checkout
    fairy = _ConnectionRecord.checkout(pool)
  File "C:\Users\pc\Desktop\Projects\python\BrizBot\venv\lib\site-packages\sqlalchemy\pool\base.py", line 712, in checkout
    rec = pool._do_get()
  File "C:\Users\pc\Desktop\Projects\python\BrizBot\venv\lib\site-packages\sqlalchemy\pool\impl.py", line 179, in _do_get
    with util.safe_reraise():
  File "C:\Users\pc\Desktop\Projects\python\BrizBot\venv\lib\site-packages\sqlalchemy\util\langhelpers.py", line 146, in __exit__
    raise exc_value.with_traceback(exc_tb)
  File "C:\Users\pc\Desktop\Projects\python\BrizBot\venv\lib\site-packages\sqlalchemy\pool\impl.py", line 177, in _do_get
    return self._create_connection()
  File "C:\Users\pc\Desktop\Projects\python\BrizBot\venv\lib\site-packages\sqlalchemy\pool\base.py", line 390, in _create_connection
    return _ConnectionRecord(self)
  File "C:\Users\pc\Desktop\Projects\python\BrizBot\venv\lib\site-packages\sqlalchemy\pool\base.py", line 674, in __init__
    self.__connect()
  File "C:\Users\pc\Desktop\Projects\python\BrizBot\venv\lib\site-packages\sqlalchemy\pool\base.py", line 900, in __connect
    with util.safe_reraise():
  File "C:\Users\pc\Desktop\Projects\python\BrizBot\venv\lib\site-packages\sqlalchemy\util\langhelpers.py", line 146, in __exit__
    raise exc_value.with_traceback(exc_tb)
  File "C:\Users\pc\Desktop\Projects\python\BrizBot\venv\lib\site-packages\sqlalchemy\pool\base.py", line 896, in __connect
    self.dbapi_connection = connection = pool._invoke_creator(self)
  File "C:\Users\pc\Desktop\Projects\python\BrizBot\venv\lib\site-packages\sqlalchemy\engine\create.py", line 643, in connect
    return dialect.connect(*cargs, **cparams)
  File "C:\Users\pc\Desktop\Projects\python\BrizBot\venv\lib\site-packages\sqlalchemy\engine\default.py", line 620, in connect
    return self.loaded_dbapi.connect(*cargs, **cparams)
  File "C:\Users\pc\Desktop\Projects\python\BrizBot\venv\lib\site-packages\sqlalchemy\dialects\mysql\aiomysql.py", line 268, in connect
    await_only(creator_fn(*arg, **kw)),
  File "C:\Users\pc\Desktop\Projects\python\BrizBot\venv\lib\site-packages\sqlalchemy\util\_concurrency_py3k.py", line 132, in await_only
    return current.parent.switch(awaitable)  # type: ignore[no-any-return,attr-defined] # noqa: E501
  File "C:\Users\pc\Desktop\Projects\python\BrizBot\venv\lib\site-packages\sqlalchemy\util\_concurrency_py3k.py", line 196, in greenlet_spawn
    value = await result
  File "C:\Users\pc\Desktop\Projects\python\BrizBot\venv\lib\site-packages\aiomysql\connection.py", line 75, in _connect
    await conn._connect()
  File "C:\Users\pc\Desktop\Projects\python\BrizBot\venv\lib\site-packages\aiomysql\connection.py", line 563, in _connect
    raise OperationalError(
pymysql.err.OperationalError: (2003, "Can't connect to MySQL server on '109.95.212.13'")

The above exception was the direct cause of the following exception:

Traceback (most recent call last):
  File "C:\Users\pc\Desktop\Projects\python\BrizBot\source\handlers\command.py", line 54, in wrapper
    await function(message, session, event)
  File "C:\Users\pc\Desktop\Projects\python\BrizBot\source\handlers\command.py", line 83, in _on_start
    chat = await get_chat(event.chat_id, session, include_user=True, include_view=True, lock=True)
  File "C:\Users\pc\Desktop\Projects\python\BrizBot\source\extensions\database\query.py", line 38, in get_chat
    return (await session.execute(get_chat_query(id, include_user, include_view, lock))).scalars().first()
  File "C:\Users\pc\Desktop\Projects\python\BrizBot\venv\lib\site-packages\sqlalchemy\ext\asyncio\session.py", line 461, in execute
    result = await greenlet_spawn(
  File "C:\Users\pc\Desktop\Projects\python\BrizBot\venv\lib\site-packages\sqlalchemy\util\_concurrency_py3k.py", line 201, in greenlet_spawn
    result = context.throw(*sys.exc_info())
  File "C:\Users\pc\Desktop\Projects\python\BrizBot\venv\lib\site-packages\sqlalchemy\orm\session.py", line 2351, in execute
    return self._execute_internal(
  File "C:\Users\pc\Desktop\Projects\python\BrizBot\venv\lib\site-packages\sqlalchemy\orm\session.py", line 2226, in _execute_internal
    conn = self._connection_for_bind(bind)
  File "C:\Users\pc\Desktop\Projects\python\BrizBot\venv\lib\site-packages\sqlalchemy\orm\session.py", line 2095, in _connection_for_bind
    return trans._connection_for_bind(engine, execution_options)
  File "<string>", line 2, in _connection_for_bind
  File "C:\Users\pc\Desktop\Projects\python\BrizBot\venv\lib\site-packages\sqlalchemy\orm\state_changes.py", line 139, in _go
    ret_value = fn(self, *arg, **kw)
  File "C:\Users\pc\Desktop\Projects\python\BrizBot\venv\lib\site-packages\sqlalchemy\orm\session.py", line 1189, in _connection_for_bind
    conn = bind.connect()
  File "C:\Users\pc\Desktop\Projects\python\BrizBot\venv\lib\site-packages\sqlalchemy\engine\base.py", line 3276, in connect
    return self._connection_cls(self)
  File "C:\Users\pc\Desktop\Projects\python\BrizBot\venv\lib\site-packages\sqlalchemy\engine\base.py", line 148, in __init__
    Connection._handle_dbapi_exception_noconnection(
  File "C:\Users\pc\Desktop\Projects\python\BrizBot\venv\lib\site-packages\sqlalchemy\engine\base.py", line 2440, in _handle_dbapi_exception_noconnection
    raise sqlalchemy_exception.with_traceback(exc_info[2]) from e
  File "C:\Users\pc\Desktop\Projects\python\BrizBot\venv\lib\site-packages\sqlalchemy\engine\base.py", line 146, in __init__
    self._dbapi_connection = engine.raw_connection()
  File "C:\Users\pc\Desktop\Projects\python\BrizBot\venv\lib\site-packages\sqlalchemy\engine\base.py", line 3300, in raw_connection
    return self.pool.connect()
  File "C:\Users\pc\Desktop\Projects\python\BrizBot\venv\lib\site-packages\sqlalchemy\pool\base.py", line 449, in connect
    return _ConnectionFairy._checkout(self)
  File "C:\Users\pc\Desktop\Projects\python\BrizBot\venv\lib\site-packages\sqlalchemy\pool\base.py", line 1263, in _checkout
    fairy = _ConnectionRecord.checkout(pool)
  File "C:\Users\pc\Desktop\Projects\python\BrizBot\venv\lib\site-packages\sqlalchemy\pool\base.py", line 712, in checkout
    rec = pool._do_get()
  File "C:\Users\pc\Desktop\Projects\python\BrizBot\venv\lib\site-packages\sqlalchemy\pool\impl.py", line 179, in _do_get
    with util.safe_reraise():
  File "C:\Users\pc\Desktop\Projects\python\BrizBot\venv\lib\site-packages\sqlalchemy\util\langhelpers.py", line 146, in __exit__
    raise exc_value.with_traceback(exc_tb)
  File "C:\Users\pc\Desktop\Projects\python\BrizBot\venv\lib\site-packages\sqlalchemy\pool\impl.py", line 177, in _do_get
    return self._create_connection()
  File "C:\Users\pc\Desktop\Projects\python\BrizBot\venv\lib\site-packages\sqlalchemy\pool\base.py", line 390, in _create_connection
    return _ConnectionRecord(self)
  File "C:\Users\pc\Desktop\Projects\python\BrizBot\venv\lib\site-packages\sqlalchemy\pool\base.py", line 674, in __init__
    self.__connect()
  File "C:\Users\pc\Desktop\Projects\python\BrizBot\venv\lib\site-packages\sqlalchemy\pool\base.py", line 900, in __connect
    with util.safe_reraise():
  File "C:\Users\pc\Desktop\Projects\python\BrizBot\venv\lib\site-packages\sqlalchemy\util\langhelpers.py", line 146, in __exit__
    raise exc_value.with_traceback(exc_tb)
  File "C:\Users\pc\Desktop\Projects\python\BrizBot\venv\lib\site-packages\sqlalchemy\pool\base.py", line 896, in __connect
    self.dbapi_connection = connection = pool._invoke_creator(self)
  File "C:\Users\pc\Desktop\Projects\python\BrizBot\venv\lib\site-packages\sqlalchemy\engine\create.py", line 643, in connect
    return dialect.connect(*cargs, **cparams)
  File "C:\Users\pc\Desktop\Projects\python\BrizBot\venv\lib\site-packages\sqlalchemy\engine\default.py", line 620, in connect
    return self.loaded_dbapi.connect(*cargs, **cparams)
  File "C:\Users\pc\Desktop\Projects\python\BrizBot\venv\lib\site-packages\sqlalchemy\dialects\mysql\aiomysql.py", line 268, in connect
    await_only(creator_fn(*arg, **kw)),
  File "C:\Users\pc\Desktop\Projects\python\BrizBot\venv\lib\site-packages\sqlalchemy\util\_concurrency_py3k.py", line 132, in await_only
    return current.parent.switch(awaitable)  # type: ignore[no-any-return,attr-defined] # noqa: E501
  File "C:\Users\pc\Desktop\Projects\python\BrizBot\venv\lib\site-packages\sqlalchemy\util\_concurrency_py3k.py", line 196, in greenlet_spawn
    value = await result
  File "C:\Users\pc\Desktop\Projects\python\BrizBot\venv\lib\site-packages\aiomysql\connection.py", line 75, in _connect
    await conn._connect()
  File "C:\Users\pc\Desktop\Projects\python\BrizBot\venv\lib\site-packages\aiomysql\connection.py", line 563, in _connect
    raise OperationalError(
sqlalchemy.exc.OperationalError: (pymysql.err.OperationalError) (2003, "Can't connect to MySQL server on '109.95.212.13'")
(Background on this error at: https://sqlalche.me/e/20/e3q8)
[2024-07-19 20:35:41,826] [INFO] [aiogram.event] [dispatcher.py:172] Update id=212626480 is handled. Duration 2359 ms by bot id=7010190829
[2024-07-19 20:35:47,970] [WARNING] [aiogram.dispatcher] [dispatcher.py:221] Sleep for 1.000000 seconds and try again... (tryings = 0, bot id = 7010190829)
[2024-07-19 20:35:58,697] [INFO] [aiogram.dispatcher] [dispatcher.py:233] Connection established (tryings = 1, bot id = 7010190829)
[2024-07-19 20:35:58,699] [INFO] [source.handlers.command] [command.py:50] event (chat '5663974991', command '6840', text '/start') has been accepted
[2024-07-19 20:36:00,922] [ERROR] [source.extensions.telegram.helpers] [helpers.py:321] event (chat '5663974991', command '6840', text '/start') message 6819 message can't be deleted for everyone
[2024-07-19 20:36:01,054] [ERROR] [source.extensions.telegram.helpers] [helpers.py:321] event (chat '5663974991', command '6840', text '/start') message 6820 message can't be deleted for everyone
[2024-07-19 20:36:01,164] [ERROR] [source.extensions.telegram.helpers] [helpers.py:321] event (chat '5663974991', command '6840', text '/start') message 6821 message can't be deleted for everyone
[2024-07-19 20:36:01,279] [ERROR] [source.extensions.telegram.helpers] [helpers.py:321] event (chat '5663974991', command '6840', text '/start') message 6822 message can't be deleted for everyone
[2024-07-19 20:36:01,414] [ERROR] [source.extensions.telegram.helpers] [helpers.py:321] event (chat '5663974991', command '6840', text '/start') message 6823 message can't be deleted for everyone
[2024-07-19 20:36:01,517] [ERROR] [source.extensions.telegram.helpers] [helpers.py:321] event (chat '5663974991', command '6840', text '/start') message 6824 message can't be deleted for everyone
[2024-07-19 20:36:01,646] [ERROR] [source.extensions.telegram.helpers] [helpers.py:321] event (chat '5663974991', command '6840', text '/start') message 6825 message can't be deleted for everyone
[2024-07-19 20:36:01,754] [ERROR] [source.extensions.telegram.helpers] [helpers.py:321] event (chat '5663974991', command '6840', text '/start') message 6826 message can't be deleted for everyone
[2024-07-19 20:36:01,881] [ERROR] [source.extensions.telegram.helpers] [helpers.py:321] event (chat '5663974991', command '6840', text '/start') message 6827 message can't be deleted for everyone
[2024-07-19 20:36:02,005] [ERROR] [source.extensions.telegram.helpers] [helpers.py:321] event (chat '5663974991', command '6840', text '/start') message 6828 message can't be deleted for everyone
[2024-07-19 20:36:02,112] [ERROR] [source.extensions.telegram.helpers] [helpers.py:321] event (chat '5663974991', command '6840', text '/start') message 6829 message can't be deleted for everyone
[2024-07-19 20:36:03,685] [INFO] [source.handlers.command] [command.py:67] event (chat '5663974991', command '6840', text '/start') has been processed
[2024-07-19 20:36:03,804] [INFO] [aiogram.event] [dispatcher.py:172] Update id=212626481 is handled. Duration 5109 ms by bot id=7010190829
[2024-07-19 20:36:03,922] [INFO] [source.handlers.ibutton] [ibutton.py:57] event (chat '5663974991', message '6841', button 'MainMenu:SHOW_ROOMS_AND_PRICES_WINDOW') has been accepted
[2024-07-19 20:36:04,453] [WARNING] [source.extensions.telegram.windows] [windows.py:69] chat.sub_window_number is 1
[2024-07-19 20:36:07,494] [INFO] [source.handlers.ibutton] [ibutton.py:71] event (chat '5663974991', message '6841', button 'MainMenu:SHOW_ROOMS_AND_PRICES_WINDOW') has been processed
[2024-07-19 20:36:07,494] [INFO] [aiogram.event] [dispatcher.py:172] Update id=212626482 is handled. Duration 4765 ms by bot id=7010190829
[2024-07-19 20:36:07,738] [INFO] [source.handlers.ibutton] [ibutton.py:57] event (chat '5663974991', message '6852', button 'NavigationMenu:LIST_FORWARD') has been accepted
[2024-07-19 20:36:08,320] [WARNING] [source.extensions.telegram.windows] [windows.py:69] chat.sub_window_number is 2
[2024-07-19 20:36:16,712] [INFO] [source.handlers.ibutton] [ibutton.py:71] event (chat '5663974991', message '6852', button 'NavigationMenu:LIST_FORWARD') has been processed
[2024-07-19 20:36:16,713] [INFO] [aiogram.event] [dispatcher.py:172] Update id=212626483 is handled. Duration 10547 ms by bot id=7010190829
[2024-07-19 20:36:17,061] [INFO] [source.handlers.ibutton] [ibutton.py:57] event (chat '5663974991', message '6859', button 'NavigationMenu:LIST_FORWARD') has been accepted
[2024-07-19 20:36:17,522] [WARNING] [source.extensions.telegram.windows] [windows.py:69] chat.sub_window_number is 3
[2024-07-19 20:36:22,695] [INFO] [source.handlers.ibutton] [ibutton.py:71] event (chat '5663974991', message '6859', button 'NavigationMenu:LIST_FORWARD') has been processed
[2024-07-19 20:36:22,695] [INFO] [aiogram.event] [dispatcher.py:172] Update id=212626484 is handled. Duration 5734 ms by bot id=7010190829
[2024-07-19 20:36:22,803] [INFO] [source.handlers.ibutton] [ibutton.py:57] event (chat '5663974991', message '6869', button 'NavigationMenu:LIST_FORWARD') has been accepted
[2024-07-19 20:36:23,267] [WARNING] [source.extensions.telegram.windows] [windows.py:69] chat.sub_window_number is 4
[2024-07-19 20:36:30,314] [INFO] [source.handlers.ibutton] [ibutton.py:71] event (chat '5663974991', message '6869', button 'NavigationMenu:LIST_FORWARD') has been processed
[2024-07-19 20:36:30,315] [INFO] [aiogram.event] [dispatcher.py:172] Update id=212626485 is handled. Duration 10891 ms by bot id=7010190829
[2024-07-19 20:36:33,758] [INFO] [source.handlers.ibutton] [ibutton.py:57] event (chat '5663974991', message '6880', button 'NavigationMenu:LIST_FORWARD') has been accepted
[2024-07-19 20:36:34,223] [WARNING] [source.extensions.telegram.windows] [windows.py:69] chat.sub_window_number is 5
[2024-07-19 20:36:39,671] [INFO] [source.handlers.ibutton] [ibutton.py:71] event (chat '5663974991', message '6880', button 'NavigationMenu:LIST_FORWARD') has been processed
[2024-07-19 20:36:39,671] [INFO] [aiogram.event] [dispatcher.py:172] Update id=212626486 is handled. Duration 6045 ms by bot id=7010190829
[2024-07-19 20:36:39,941] [INFO] [source.handlers.ibutton] [ibutton.py:57] event (chat '5663974991', message '6891', button 'NavigationMenu:LIST_FORWARD') has been accepted
[2024-07-19 20:36:41,123] [WARNING] [source.extensions.telegram.windows] [windows.py:69] chat.sub_window_number is 6
[2024-07-19 20:36:46,410] [INFO] [source.handlers.ibutton] [ibutton.py:71] event (chat '5663974991', message '6891', button 'NavigationMenu:LIST_FORWARD') has been processed
[2024-07-19 20:36:46,410] [INFO] [aiogram.event] [dispatcher.py:172] Update id=212626487 is handled. Duration 10015 ms by bot id=7010190829
[2024-07-19 20:36:46,508] [INFO] [source.handlers.ibutton] [ibutton.py:57] event (chat '5663974991', message '6891', button 'NavigationMenu:LIST_FORWARD') has been accepted
[2024-07-19 20:36:46,973] [WARNING] [source.extensions.telegram.windows] [windows.py:69] chat.sub_window_number is 7
[2024-07-19 20:36:51,750] [INFO] [source.handlers.ibutton] [ibutton.py:71] event (chat '5663974991', message '6891', button 'NavigationMenu:LIST_FORWARD') has been processed
[2024-07-19 20:36:51,750] [INFO] [aiogram.event] [dispatcher.py:172] Update id=212626488 is handled. Duration 11344 ms by bot id=7010190829
[2024-07-19 20:36:51,845] [INFO] [source.handlers.ibutton] [ibutton.py:57] event (chat '5663974991', message '6902', button 'NavigationMenu:LIST_FORWARD') has been accepted
[2024-07-19 20:36:52,306] [WARNING] [source.extensions.telegram.windows] [windows.py:69] chat.sub_window_number is 8
[2024-07-19 20:36:56,995] [INFO] [source.handlers.ibutton] [ibutton.py:71] event (chat '5663974991', message '6902', button 'NavigationMenu:LIST_FORWARD') has been processed
[2024-07-19 20:36:56,995] [INFO] [aiogram.event] [dispatcher.py:172] Update id=212626489 is handled. Duration 10782 ms by bot id=7010190829
[2024-07-19 20:36:57,101] [INFO] [source.handlers.ibutton] [ibutton.py:57] event (chat '5663974991', message '6913', button 'NavigationMenu:LIST_FORWARD') has been accepted
[2024-07-19 20:36:57,555] [WARNING] [source.extensions.telegram.windows] [windows.py:69] chat.sub_window_number is 9
[2024-07-19 20:37:01,885] [INFO] [source.handlers.ibutton] [ibutton.py:71] event (chat '5663974991', message '6913', button 'NavigationMenu:LIST_FORWARD') has been processed
[2024-07-19 20:37:01,886] [INFO] [aiogram.event] [dispatcher.py:172] Update id=212626490 is handled. Duration 11687 ms by bot id=7010190829
[2024-07-19 20:37:10,664] [INFO] [source.handlers.ibutton] [ibutton.py:57] event (chat '5663974991', message '6934', button 'NavigationMenu:LIST_FORWARD') has been accepted
[2024-07-19 20:37:11,122] [WARNING] [source.extensions.telegram.windows] [windows.py:69] chat.sub_window_number is 10
[2024-07-19 20:37:14,619] [INFO] [source.handlers.ibutton] [ibutton.py:71] event (chat '5663974991', message '6934', button 'NavigationMenu:LIST_FORWARD') has been processed
[2024-07-19 20:37:14,619] [INFO] [aiogram.event] [dispatcher.py:172] Update id=212626491 is handled. Duration 4172 ms by bot id=7010190829
[2024-07-19 20:40:20,928] [INFO] [source.handlers.ibutton] [ibutton.py:57] event (chat '5663974991', message '6938', button 'NavigationMenu:LIST_BACK') has been accepted
[2024-07-19 20:40:21,640] [WARNING] [source.extensions.telegram.windows] [windows.py:69] chat.sub_window_number is 9
[2024-07-19 20:40:24,719] [INFO] [source.handlers.ibutton] [ibutton.py:71] event (chat '5663974991', message '6938', button 'NavigationMenu:LIST_BACK') has been processed
[2024-07-19 20:40:24,719] [INFO] [aiogram.event] [dispatcher.py:172] Update id=212626492 is handled. Duration 4500 ms by bot id=7010190829
[2024-07-19 20:40:24,918] [INFO] [source.handlers.ibutton] [ibutton.py:57] event (chat '5663974991', message '6949', button 'NavigationMenu:LIST_FORWARD') has been accepted
[2024-07-19 20:40:25,377] [WARNING] [source.extensions.telegram.windows] [windows.py:69] chat.sub_window_number is 10
[2024-07-19 20:40:32,235] [INFO] [source.handlers.ibutton] [ibutton.py:71] event (chat '5663974991', message '6949', button 'NavigationMenu:LIST_FORWARD') has been processed
[2024-07-19 20:40:32,235] [INFO] [aiogram.event] [dispatcher.py:172] Update id=212626493 is handled. Duration 9250 ms by bot id=7010190829
[2024-07-19 20:40:49,348] [INFO] [source.handlers.ibutton] [ibutton.py:57] event (chat '5663974991', message '6955', button 'NavigationMenu:LIST_BACK') has been accepted
[2024-07-19 20:40:49,808] [WARNING] [source.extensions.telegram.windows] [windows.py:69] chat.sub_window_number is 9
[2024-07-19 20:40:53,791] [INFO] [source.handlers.ibutton] [ibutton.py:71] event (chat '5663974991', message '6955', button 'NavigationMenu:LIST_BACK') has been processed
[2024-07-19 20:40:53,791] [INFO] [aiogram.event] [dispatcher.py:172] Update id=212626494 is handled. Duration 4967 ms by bot id=7010190829
[2024-07-19 20:40:53,882] [INFO] [source.handlers.ibutton] [ibutton.py:57] event (chat '5663974991', message '6966', button 'NavigationMenu:LIST_FORWARD') has been accepted
[2024-07-19 20:40:54,340] [WARNING] [source.extensions.telegram.windows] [windows.py:69] chat.sub_window_number is 10
[2024-07-19 20:40:58,036] [INFO] [source.handlers.ibutton] [ibutton.py:71] event (chat '5663974991', message '6966', button 'NavigationMenu:LIST_FORWARD') has been processed
[2024-07-19 20:40:58,037] [INFO] [aiogram.event] [dispatcher.py:172] Update id=212626495 is handled. Duration 4405 ms by bot id=7010190829
[2024-07-19 20:41:18,732] [INFO] [source.handlers.ibutton] [ibutton.py:57] event (chat '5663974991', message '6972', button 'NavigationMenu:LIST_BACK') has been accepted
[2024-07-19 20:41:19,194] [WARNING] [source.extensions.telegram.windows] [windows.py:69] chat.sub_window_number is 9
[2024-07-19 20:41:23,261] [INFO] [source.handlers.ibutton] [ibutton.py:71] event (chat '5663974991', message '6972', button 'NavigationMenu:LIST_BACK') has been processed
[2024-07-19 20:41:23,261] [INFO] [aiogram.event] [dispatcher.py:172] Update id=212626496 is handled. Duration 4890 ms by bot id=7010190829
[2024-07-19 20:41:23,417] [INFO] [source.handlers.ibutton] [ibutton.py:57] event (chat '5663974991', message '6983', button 'NavigationMenu:LIST_FORWARD') has been accepted
[2024-07-19 20:41:23,880] [WARNING] [source.extensions.telegram.windows] [windows.py:69] chat.sub_window_number is 10
[2024-07-19 20:41:28,267] [INFO] [source.handlers.ibutton] [ibutton.py:71] event (chat '5663974991', message '6983', button 'NavigationMenu:LIST_FORWARD') has been processed
[2024-07-19 20:41:28,267] [INFO] [aiogram.event] [dispatcher.py:172] Update id=212626497 is handled. Duration 7265 ms by bot id=7010190829
[2024-07-19 20:42:26,377] [INFO] [source.handlers.ibutton] [ibutton.py:57] event (chat '5663974991', message '6988', button 'NavigationMenu:LIST_BACK') has been accepted
[2024-07-19 20:42:26,838] [WARNING] [source.extensions.telegram.windows] [windows.py:69] chat.sub_window_number is 9
[2024-07-19 20:42:30,219] [INFO] [source.handlers.ibutton] [ibutton.py:71] event (chat '5663974991', message '6988', button 'NavigationMenu:LIST_BACK') has been processed
[2024-07-19 20:42:30,220] [INFO] [aiogram.event] [dispatcher.py:172] Update id=212626498 is handled. Duration 4140 ms by bot id=7010190829
[2024-07-19 20:42:30,338] [INFO] [source.handlers.ibutton] [ibutton.py:57] event (chat '5663974991', message '6999', button 'NavigationMenu:LIST_BACK') has been accepted
[2024-07-19 20:42:30,797] [WARNING] [source.extensions.telegram.windows] [windows.py:69] chat.sub_window_number is 8
[2024-07-19 20:42:35,233] [INFO] [source.handlers.ibutton] [ibutton.py:71] event (chat '5663974991', message '6999', button 'NavigationMenu:LIST_BACK') has been processed
[2024-07-19 20:42:35,234] [INFO] [aiogram.event] [dispatcher.py:172] Update id=212626499 is handled. Duration 5953 ms by bot id=7010190829
[2024-07-19 20:42:35,332] [INFO] [source.handlers.ibutton] [ibutton.py:57] event (chat '5663974991', message '7009', button 'NavigationMenu:LOAD_PREV_MENU') has been accepted
[2024-07-19 20:42:38,457] [INFO] [source.handlers.ibutton] [ibutton.py:71] event (chat '5663974991', message '7009', button 'NavigationMenu:LOAD_PREV_MENU') has been processed
[2024-07-19 20:42:38,458] [INFO] [aiogram.event] [dispatcher.py:172] Update id=212626500 is handled. Duration 6202 ms by bot id=7010190829
[2024-07-19 20:42:39,673] [INFO] [aiogram.dispatcher] [dispatcher.py:554] Polling stopped
[2024-07-19 20:42:39,674] [INFO] [source.handlers.dispather] [dispather.py:49] Dispatcher has been shut down
[2024-07-19 20:42:39,675] [INFO] [aiogram.dispatcher] [dispatcher.py:359] Polling stopped for bot @pirat_themed_guest_house_bot id=7010190829 - 'Briz'
[2024-07-19 20:42:39,949] [INFO] [source.persistance.database] [database.py:113] Database context has been closed
